<?xml version="1.0"?>
<robot xmlns:xacro="http://www.ros.org/wiki/xacro">

<!-- ########################## HEXAPOD COXA GENERATOR ############################ -->
    <xacro:macro name="generate_cox" params="side position joint_type:=COX">
        
        <xacro:generate_IdOr_link_same_mesh link_name="${side}_${position}_COX_link" stl="coxa_${side}_${position}"/>
        
        <xacro:property name="coords" value="${origins[side][position][joint_type]}"/>
        <joint name="${side}_${position}_COX_joint" type="revolute" >
            <origin xyz="${coords['x']} ${coords['y']} ${coords['z']}" rpy="0 0 0"/>
            <parent link="body_link"/>
            <child link="${side}_${position}_COX_link"/>
            <axis xyz="0 0 1" rpy="0 0 0"/>
            <!-- <limit upper="${PI}" lower="${PI}" effort="10000" velocity="1000"/> -->
            <limit upper="1.0" lower="-1.0" effort="1000.0" velocity="0.5"/>
            <!-- <joint_properties damping="1.0" friction="1.0"/> -->
        </joint>

         <gazebo reference="${side}_${position}_COX_link">
             <mu1 value="${HEX_MU1}"/>
             <mu2 value="${HEX_MU2}"/>
             <kp value="${HEX_KP}"/>
             <kd value="${HEX_KD}"/>
              <material>Gazebo/Green</material>
        </gazebo>
    </xacro:macro>
<!-- ########################## END COXA GENERATOR ############################ -->

</robot>
