<?xml version="1.0"?>
<robot xmlns:xacro="http://www.ros.org/wiki/xacro">

    <xacro:property name="DOCK_MASS" value="0.1"/>

    <xacro:property name="DOCK_LENGTH" value="0.4"/>
    <xacro:property name="DOCK_WIDTH" value="0.05"/>
    <xacro:property name="DOCK_HEIGHT" value="0.3"/>

    <xacro:property name="DOCK_X_OFFSET" value="0.5"/>
    <xacro:property name="DOCK_Y_OFFSET" value="0.15"/>

    <xacro:property name="SCALE" value="1"/>

    <xacro:macro name="DOCK_LINK_ORIGIN">
        <origin xyz="${DOCK_X_OFFSET} ${DOCK_Y_OFFSET} 0" rpy="0 0 0" />
    </xacro:macro>

<!-- ########################## DOCK GENERATOR ############################ -->
    <xacro:macro name="generate_leg_middle" params="side">

        <link name="dock_${side}_link">
            <collision>
                <!-- <xacro:DOCK_LINK_ORIGIN/> -->
                <xacro:generate_geometry shape="box" x="${DOCK_LENGTH}" y="${DOCK_WIDTH}" z="${DOCK_HEIGHT}"/>
                <!-- <geometry>
                    <mesh filename="package://dockbot/meshes/dockbot_side.dae" scale="${SCALE} ${SCALE} ${SCALE}"/>
                </geometry> -->
            </collision>

            <visual>
                <!-- <xacro:DOCK_LINK_ORIGIN/> -->
                <geometry>
                    <mesh filename="package://dockbot/meshes/dockbot_side.dae" scale="${SCALE} ${SCALE} ${SCALE}"/>
                </geometry>
            </visual>

            <xacro:MINIMUM_INERTIAL/>
        </link>

        <joint type="revolute" name="dock_${side}_joint">
            <xacro:if value="${side == 'left'}">
                <origin xyz="-${DOCK_X_OFFSET} ${DOCK_Y_OFFSET} 0" rpy="0 0 0"/>
            </xacro:if>
            <!-- Right Dock Y value is inverted (-Y) -->
            <xacro:if value="${side == 'right'}">
                <origin xyz="${DOCK_X_OFFSET} ${DOCK_Y_OFFSET} 0" rpy="0 0 ${PI}"/>
            </xacro:if>

            <!-- <parent link="dock_base_link"/> -->
            <parent link="base_link"/>
            <child link="dock_${side}_link"/>
            <axis xyz="0 0 1" rpy="0 0 0"/>
            <!-- <limit upper="${PI}" lower="${PI}" effort="10000" velocity="1000"/> -->
            <limit upper="1.0}" lower="-1.0" effort="10000.0" velocity="0.5"/>
            <!-- <joint_properties damping="1.0" friction="1.0"/> -->
        </joint>

         <gazebo reference="dock_${side}_link">
              <mu1 value="${DOCK_MU1}"/>
              <mu2 value="${DOCK_MU2}"/>
              <kp value="${DOCK_KP}"/>
              <kd value="${DOCK_KD}"/>
              <material>Gazebo/Green</material>
             <xacro:if value="${side == 'right'}">
                 <material>Gazebo/Red</material>
            </xacro:if>
        </gazebo>

        <transmission name="${side}_dock_transmission">
            <type>transmission_interface/SimpleTransmission</type>
            <joint name="dock_${side}_joint">
                <!-- <hardwareInterface>hardware_interface/EffortJointInterface</hardwareInterface> -->
                <hardwareInterface>EffortJointInterface</hardwareInterface>
            </joint>
            <actuator name="${side}_dock_actuator">
                <mechanicalReduction>7</mechanicalReduction>
                <hardwareInterface>EffortJointInterface</hardwareInterface>
            </actuator>
        </transmission>

    </xacro:macro>
<!-- ########################## END DOCK GENERATOR ############################ -->

</robot>
