<?xml version="1.0" encoding="utf-8"?>
<!-- =================================================================================== -->
<!-- |    This document was autogenerated by xacro from hexapod.urdf.xacro             | -->
<!-- |    EDITING THIS FILE BY HAND IS NOT RECOMMENDED                                 | -->
<!-- =================================================================================== -->
<robot name="hexapod">
  <!-- Dynamic contact stiffness. This determines if the link material is closer to marble (very rigid, bigger values) or more like rubber (soft material, lower values). It's essentially how much it deforms over a long period of time, exerting its pressure. -->
  <!-- ################################################################## -->
  <!-- ########################## GENERATORS ############################ -->
  <!-- ################################################################## -->
  <!--########################## GENERATE IDENTITY ORIGIN LINK WITH IDENTICAL COLLISION/VISUAL MESH XACRO ##########################-->
  <!-- <xacro:macro name="generate_joint" params="joint_name parent child ">
        <link name="${link_name}">
            <collision>
                <xacro:add_stl scale="${SCALE}" fname="${stl}"/>
            </collision>
            <visual>
                <xacro:add_stl scale="${SCALE}" fname="${stl}"/>
            </visual>
            <xacro:MINIMUM_INERTIAL/>
        </link>
    </xacro:macro> -->
  <!-- ################################################################## -->
  <!-- ############################ COLORS ############################## -->
  <!-- ################################################################## -->
  <!-- These are for URDF coloring. Gazebo colors begin with capital letters -->
  <material name="blue">
    <color rgba="0.0 0.0 0.8 1.0"/>
  </material>
  <material name="green">
    <color rgba="0.0 0.8 0.0 1.0"/>
  </material>
  <material name="grey">
    <color rgba="0.7 0.7 0.7 1.0"/>
  </material>
  <material name="lightGrey">
    <color rgba="0.9 0.9 0.9 1.0"/>
  </material>
  <material name="darkGrey">
    <color rgba="0.2 0.2 0.2 1.0"/>
  </material>
  <material name="red">
    <color rgba="0.8 0.0 0.0 1.0"/>
  </material>
  <material name="white">
    <color rgba="1.0 1.0 1.0 1.0"/>
  </material>
  <material name="orange">
    <color rgba="1.0 0.69 0.0 1.0"/>
  </material>
  <!-- ########################## END HEX GENERATOR ############################ -->
  <!-- <xacro:include filename="$(find hexapod)/urdf/general.urdf.xacro"/> -->
  <!-- <xacro:macro name="get_origin" params="side position joint_type"> -->
  <!-- <xacro:property name="coords" value="${origins['${side}_${position}_${joint_type}']}"/> -->
  <!-- </xacro:macro> -->
  <!-- <xacro:property name="mapping" value="${None}"/> -->
  <!-- <xacro:property name="mapping" value="${mapping.get('handedness','right')}"/> -->
  <!-- <xacro:property name="proximal_len" value="${properties['link_lengths'][finger]['proximal']}"/> -->
  <!-- ########################## END DOCK GENERATOR ############################ -->
  <!-- ########################## END DOCK GENERATOR ############################ -->
  <!-- <xacro:property name="DOCK_MASS" value="0.01"/> -->
  <!-- <xacro:property name="FEM_WJ_X" value="-0.070807"/>
    <xacro:property name="FEM_WJ_Y" value="0.02"/>
    <xacro:property name="FEM_WJ_Z" value="0.064307"/> -->
  <!-- FROM ORIGIN -->
  <!-- <xacro:macro name="FEM_MOTOR_WHEEL_JOINT_ORIGIN">
        <origin xyz="${FEM_WJ_X} ${FEM_WJ_Y} ${FEM_WJ_Z}" rpy="${PI_2} ${PI} 0" />
    </xacro:macro> -->
  <!-- ########################## END DOCK GENERATOR ############################ -->
  <!-- ########################## END HEXAPOD LEG GENERATOR ############################ -->
  <!-- <xacro:include filename="$(find hexapod)/urdf/hexapod.gazebo" /> -->
  <!-- Footprint link -->
  <link name="base_footprint">
    <visual>
      <geometry>
        <cylinder length="0.001" radius="0.01"/>
      </geometry>
    </visual>
  </link>
  <!-- Floating-base Joint -->
  <!-- <joint name="floating_base" type="fixed">
        <origin xyz="0 0 0" rpy="0 0 0"/>
        <parent link="base_footprint"/>
        <child link="heaxpod_body_link"/>
    </joint> -->
  <!-- <xacro:generate_body/> -->
  <!-- ########################## BODY LINK ############################ -->
  <!-- Body link -->
  <link name="body_link">
    <collision>
      <geometry>
        <mesh filename="package://hexapod/urdf/models/base.stl" scale="0.001 0.001 0.001"/>
      </geometry>
    </collision>
    <visual>
      <geometry>
        <mesh filename="package://hexapod/urdf/models/base.stl" scale="0.001 0.001 0.001"/>
      </geometry>
    </visual>
    <inertial>
      <origin rpy="0 0 0" xyz="0 0 0"/>
      <mass value="0.1"/>
      <inertia ixx="0.02" ixy="0.0" ixz="0.0" iyy="0.02" iyz="0.0" izz="0.02"/>
      <!-- <inertia ixx="1.66666666667e-08" ixy="0.0" ixz="0.0"
                      iyy="1.66666666667e-08" iyz="0.0"
                      izz="1.66666666667e-08"/> -->
    </inertial>
  </link>
  <joint name="body_joint" type="fixed">
    <parent link="base_footprint"/>
    <child link="body_link"/>
  </joint>
  <gazebo reference="body_link">
    <mu1 value="10.0"/>
    <mu2 value="10.0"/>
    <kp value="10000.0"/>
    <kd value="10000.0"/>
    <material>Gazebo/Red</material>
  </gazebo>
  <link name="R_M_COX_link">
    <collision>
      <geometry>
        <mesh filename="package://hexapod/urdf/models/coxa_2_wheels_M_fo.stl" scale="0.001 0.001 0.001"/>
      </geometry>
    </collision>
    <visual>
      <geometry>
        <mesh filename="package://hexapod/urdf/models/coxa_2_wheels_M_fo.stl" scale="0.001 0.001 0.001"/>
      </geometry>
    </visual>
    <inertial>
      <origin rpy="0 0 0" xyz="0 0 0"/>
      <mass value="0.1"/>
      <inertia ixx="0.02" ixy="0.0" ixz="0.0" iyy="0.02" iyz="0.0" izz="0.02"/>
      <!-- <inertia ixx="1.66666666667e-08" ixy="0.0" ixz="0.0"
                      iyy="1.66666666667e-08" iyz="0.0"
                      izz="1.66666666667e-08"/> -->
    </inertial>
  </link>
  <joint name="R_M_COX_joint" type="revolute">
    <origin rpy="0 0 0" xyz="-0.0635 0 0.007"/>
    <parent link="body_link"/>
    <child link="R_M_COX_link"/>
    <axis rpy="0 0 0" xyz="0 0 1"/>
    <!-- <limit upper="${PI}" lower="${PI}" effort="10000" velocity="1000"/> -->
    <limit effort="1000.0" lower="-1.0" upper="1.0" velocity="0.5"/>
    <!-- <joint_properties damping="1.0" friction="1.0"/> -->
  </joint>
  <gazebo reference="R_M_COX_link">
    <mu1 value="10.0"/>
    <mu2 value="10.0"/>
    <kp value="10000.0"/>
    <kd value="10000.0"/>
    <material>Gazebo/Green</material>
  </gazebo>
  <!-- <transmission name="${side}_dock_transmission">
            <type>transmission_interface/SimpleTransmission</type>
            <joint name="dock_${side}_joint"> -->
  <!-- <hardwareInterface>hardware_interface/EffortJointInterface</hardwareInterface> -->
  <!-- <hardwareInterface>EffortJointInterface</hardwareInterface>
            </joint>
            <actuator name="${side}_dock_actuator">
                <mechanicalReduction>7</mechanicalReduction>
                <hardwareInterface>EffortJointInterface</hardwareInterface>
            </actuator>
        </transmission> -->
  <link name="R_M_FEM_link">
    <collision>
      <geometry>
        <mesh filename="package://hexapod/urdf/models/femur_no_wheel_M_fo.stl" scale="0.001 0.001 0.001"/>
      </geometry>
    </collision>
    <visual>
      <geometry>
        <mesh filename="package://hexapod/urdf/models/femur_no_wheel_M_fo.stl" scale="0.001 0.001 0.001"/>
      </geometry>
    </visual>
    <inertial>
      <origin rpy="0 0 0" xyz="0 0 0"/>
      <mass value="0.1"/>
      <inertia ixx="0.02" ixy="0.0" ixz="0.0" iyy="0.02" iyz="0.0" izz="0.02"/>
      <!-- <inertia ixx="1.66666666667e-08" ixy="0.0" ixz="0.0"
                      iyy="1.66666666667e-08" iyz="0.0"
                      izz="1.66666666667e-08"/> -->
    </inertial>
  </link>
  <joint name="R_M_FEM_joint" type="revolute">
    <origin rpy="0 0 0" xyz="-0.007261 -0.015954 0.057284"/>
    <parent link="R_M_COX_link"/>
    <child link="R_M_FEM_link"/>
    <axis rpy="0 0 0" xyz="0 1 0"/>
    <!-- <limit upper="${PI}" lower="${PI}" effort="10000" velocity="1000"/> -->
    <limit effort="1000.0" lower="-1.0" upper="1.0" velocity="0.5"/>
    <!-- <joint_properties damping="1.0" friction="1.0"/> -->
  </joint>
  <gazebo reference="R_M_FEM_link">
    <mu1 value="10.0"/>
    <mu2 value="10.0"/>
    <kp value="10000.0"/>
    <kd value="10000.0"/>
    <material>Gazebo/Blue</material>
  </gazebo>
  <!-- <transmission name="${side}_dock_transmission">
            <type>transmission_interface/SimpleTransmission</type>
            <joint name="dock_${side}_joint"> -->
  <!-- <hardwareInterface>hardware_interface/EffortJointInterface</hardwareInterface> -->
  <!-- <hardwareInterface>EffortJointInterface</hardwareInterface>
            </joint>
            <actuator name="${side}_dock_actuator">
                <mechanicalReduction>7</mechanicalReduction>
                <hardwareInterface>EffortJointInterface</hardwareInterface>
            </actuator>
        </transmission> -->
  <!-- <xacro:generate_tibia side="left"/> -->
  <link name="R_F_COX_link">
    <collision>
      <geometry>
        <mesh filename="package://hexapod/urdf/models/coxa_2_wheels_F_fo.stl" scale="0.001 0.001 0.001"/>
      </geometry>
    </collision>
    <visual>
      <geometry>
        <mesh filename="package://hexapod/urdf/models/coxa_2_wheels_F_fo.stl" scale="0.001 0.001 0.001"/>
      </geometry>
    </visual>
    <inertial>
      <origin rpy="0 0 0" xyz="0 0 0"/>
      <mass value="0.1"/>
      <inertia ixx="0.02" ixy="0.0" ixz="0.0" iyy="0.02" iyz="0.0" izz="0.02"/>
      <!-- <inertia ixx="1.66666666667e-08" ixy="0.0" ixz="0.0"
                      iyy="1.66666666667e-08" iyz="0.0"
                      izz="1.66666666667e-08"/> -->
    </inertial>
  </link>
  <joint name="R_F_COX_joint" type="revolute">
    <origin rpy="0 0 0" xyz="-0.057077 -0.066312 0.007"/>
    <parent link="body_link"/>
    <child link="R_F_COX_link"/>
    <axis rpy="0 0 0" xyz="0 0 1"/>
    <!-- <limit upper="${PI}" lower="${PI}" effort="10000" velocity="1000"/> -->
    <limit effort="1000.0" lower="-1.0" upper="1.0" velocity="0.5"/>
    <!-- <joint_properties damping="1.0" friction="1.0"/> -->
  </joint>
  <gazebo reference="R_F_COX_link">
    <mu1 value="10.0"/>
    <mu2 value="10.0"/>
    <kp value="10000.0"/>
    <kd value="10000.0"/>
    <material>Gazebo/Green</material>
  </gazebo>
  <!-- <transmission name="${side}_dock_transmission">
            <type>transmission_interface/SimpleTransmission</type>
            <joint name="dock_${side}_joint"> -->
  <!-- <hardwareInterface>hardware_interface/EffortJointInterface</hardwareInterface> -->
  <!-- <hardwareInterface>EffortJointInterface</hardwareInterface>
            </joint>
            <actuator name="${side}_dock_actuator">
                <mechanicalReduction>7</mechanicalReduction>
                <hardwareInterface>EffortJointInterface</hardwareInterface>
            </actuator>
        </transmission> -->
  <link name="R_F_FEM_link">
    <collision>
      <geometry>
        <mesh filename="package://hexapod/urdf/models/femur_no_wheel_F_fo.stl" scale="0.001 0.001 0.001"/>
      </geometry>
    </collision>
    <visual>
      <geometry>
        <mesh filename="package://hexapod/urdf/models/femur_no_wheel_F_fo.stl" scale="0.001 0.001 0.001"/>
      </geometry>
    </visual>
    <inertial>
      <origin rpy="0 0 0" xyz="0 0 0"/>
      <mass value="0.1"/>
      <inertia ixx="0.02" ixy="0.0" ixz="0.0" iyy="0.02" iyz="0.0" izz="0.02"/>
      <!-- <inertia ixx="1.66666666667e-08" ixy="0.0" ixz="0.0"
                      iyy="1.66666666667e-08" iyz="0.0"
                      izz="1.66666666667e-08"/> -->
    </inertial>
  </link>
  <joint name="R_F_FEM_joint" type="revolute">
    <origin rpy="0 0 0" xyz="0.001689 -0.017448 0.057284"/>
    <parent link="R_F_COX_link"/>
    <child link="R_F_FEM_link"/>
    <axis rpy="0 0 0" xyz="0 1 0"/>
    <!-- <limit upper="${PI}" lower="${PI}" effort="10000" velocity="1000"/> -->
    <limit effort="1000.0" lower="-1.0" upper="1.0" velocity="0.5"/>
    <!-- <joint_properties damping="1.0" friction="1.0"/> -->
  </joint>
  <gazebo reference="R_F_FEM_link">
    <mu1 value="10.0"/>
    <mu2 value="10.0"/>
    <kp value="10000.0"/>
    <kd value="10000.0"/>
    <material>Gazebo/Blue</material>
  </gazebo>
  <!-- <transmission name="${side}_dock_transmission">
            <type>transmission_interface/SimpleTransmission</type>
            <joint name="dock_${side}_joint"> -->
  <!-- <hardwareInterface>hardware_interface/EffortJointInterface</hardwareInterface> -->
  <!-- <hardwareInterface>EffortJointInterface</hardwareInterface>
            </joint>
            <actuator name="${side}_dock_actuator">
                <mechanicalReduction>7</mechanicalReduction>
                <hardwareInterface>EffortJointInterface</hardwareInterface>
            </actuator>
        </transmission> -->
  <!-- <xacro:generate_tibia side="left"/> -->
  <link name="R_B_COX_link">
    <collision>
      <geometry>
        <mesh filename="package://hexapod/urdf/models/coxa_2_wheels_B_fo.stl" scale="0.001 0.001 0.001"/>
      </geometry>
    </collision>
    <visual>
      <geometry>
        <mesh filename="package://hexapod/urdf/models/coxa_2_wheels_B_fo.stl" scale="0.001 0.001 0.001"/>
      </geometry>
    </visual>
    <inertial>
      <origin rpy="0 0 0" xyz="0 0 0"/>
      <mass value="0.1"/>
      <inertia ixx="0.02" ixy="0.0" ixz="0.0" iyy="0.02" iyz="0.0" izz="0.02"/>
      <!-- <inertia ixx="1.66666666667e-08" ixy="0.0" ixz="0.0"
                      iyy="1.66666666667e-08" iyz="0.0"
                      izz="1.66666666667e-08"/> -->
    </inertial>
  </link>
  <joint name="R_B_COX_joint" type="revolute">
    <origin rpy="0 0 0" xyz="-0.057077 0.066312 0.007"/>
    <parent link="body_link"/>
    <child link="R_B_COX_link"/>
    <axis rpy="0 0 0" xyz="0 0 1"/>
    <!-- <limit upper="${PI}" lower="${PI}" effort="10000" velocity="1000"/> -->
    <limit effort="1000.0" lower="-1.0" upper="1.0" velocity="0.5"/>
    <!-- <joint_properties damping="1.0" friction="1.0"/> -->
  </joint>
  <gazebo reference="R_B_COX_link">
    <mu1 value="10.0"/>
    <mu2 value="10.0"/>
    <kp value="10000.0"/>
    <kd value="10000.0"/>
    <material>Gazebo/Green</material>
  </gazebo>
  <!-- <transmission name="${side}_dock_transmission">
            <type>transmission_interface/SimpleTransmission</type>
            <joint name="dock_${side}_joint"> -->
  <!-- <hardwareInterface>hardware_interface/EffortJointInterface</hardwareInterface> -->
  <!-- <hardwareInterface>EffortJointInterface</hardwareInterface>
            </joint>
            <actuator name="${side}_dock_actuator">
                <mechanicalReduction>7</mechanicalReduction>
                <hardwareInterface>EffortJointInterface</hardwareInterface>
            </actuator>
        </transmission> -->
  <link name="R_B_FEM_link">
    <collision>
      <geometry>
        <mesh filename="package://hexapod/urdf/models/femur_no_wheel_B_fo.stl" scale="0.001 0.001 0.001"/>
      </geometry>
    </collision>
    <visual>
      <geometry>
        <mesh filename="package://hexapod/urdf/models/femur_no_wheel_B_fo.stl" scale="0.001 0.001 0.001"/>
      </geometry>
    </visual>
    <inertial>
      <origin rpy="0 0 0" xyz="0 0 0"/>
      <mass value="0.1"/>
      <inertia ixx="0.02" ixy="0.0" ixz="0.0" iyy="0.02" iyz="0.0" izz="0.02"/>
      <!-- <inertia ixx="1.66666666667e-08" ixy="0.0" ixz="0.0"
                      iyy="1.66666666667e-08" iyz="0.0"
                      izz="1.66666666667e-08"/> -->
    </inertial>
  </link>
  <joint name="R_B_FEM_joint" type="revolute">
    <origin rpy="0 0 0" xyz="-0.014265 -0.010186 0.057284"/>
    <parent link="R_B_COX_link"/>
    <child link="R_B_FEM_link"/>
    <axis rpy="0 0 0" xyz="0 1 0"/>
    <!-- <limit upper="${PI}" lower="${PI}" effort="10000" velocity="1000"/> -->
    <limit effort="1000.0" lower="-1.0" upper="1.0" velocity="0.5"/>
    <!-- <joint_properties damping="1.0" friction="1.0"/> -->
  </joint>
  <gazebo reference="R_B_FEM_link">
    <mu1 value="10.0"/>
    <mu2 value="10.0"/>
    <kp value="10000.0"/>
    <kd value="10000.0"/>
    <material>Gazebo/Blue</material>
  </gazebo>
  <!-- <transmission name="${side}_dock_transmission">
            <type>transmission_interface/SimpleTransmission</type>
            <joint name="dock_${side}_joint"> -->
  <!-- <hardwareInterface>hardware_interface/EffortJointInterface</hardwareInterface> -->
  <!-- <hardwareInterface>EffortJointInterface</hardwareInterface>
            </joint>
            <actuator name="${side}_dock_actuator">
                <mechanicalReduction>7</mechanicalReduction>
                <hardwareInterface>EffortJointInterface</hardwareInterface>
            </actuator>
        </transmission> -->
  <!-- <xacro:generate_tibia side="left"/> -->
</robot>

