<?xml version="1.0" encoding="utf-8"?>
<!-- =================================================================================== -->
<!-- |    This document was autogenerated by xacro from hexapod.urdf.xacro             | -->
<!-- |    EDITING THIS FILE BY HAND IS NOT RECOMMENDED                                 | -->
<!-- =================================================================================== -->
<robot name="hexapod" xmlns:xacro="http://www.ros.org/wiki/xacro">
  <!-- Dynamic contact stiffness. This determines if the link material is closer to marble (very rigid, bigger values) or more like rubber (soft material, lower values). It's essentially how much it deforms over a long period of time, exerting its pressure. -->
  <!-- ################################################################## -->
  <!-- ########################## GENERATORS ############################ -->
  <!-- ################################################################## -->
  <!-- ################################################################## -->
  <!-- ############################ COLORS ############################## -->
  <!-- ################################################################## -->
  <!-- These are for URDF coloring. Gazebo colors begin with capital letters -->
  <material name="blue">
    <color rgba="0.0 0.0 0.8 1.0"/>
  </material>
  <material name="green">
    <color rgba="0.0 0.8 0.0 1.0"/>
  </material>
  <material name="grey">
    <color rgba="0.7 0.7 0.7 1.0"/>
  </material>
  <material name="lightGrey">
    <color rgba="0.9 0.9 0.9 1.0"/>
  </material>
  <material name="darkGrey">
    <color rgba="0.2 0.2 0.2 1.0"/>
  </material>
  <material name="red">
    <color rgba="0.8 0.0 0.0 1.0"/>
  </material>
  <material name="white">
    <color rgba="1.0 1.0 1.0 1.0"/>
  </material>
  <material name="orange">
    <color rgba="1.0 0.69 0.0 1.0"/>
  </material>
  <!-- ########################## END HEX GENERATOR ############################ -->
  <!-- <xacro:property name="DOCK_MASS" value="0.01"/> -->
  <!-- ########################## END DOCK GENERATOR ############################ -->
  <!-- <xacro:property name="DOCK_MASS" value="0.01"/> -->
  <!-- ########################## END DOCK GENERATOR ############################ -->
  <!-- <xacro:property name="DOCK_MASS" value="0.01"/> -->
  <!-- <xacro:property name="FEM_WJ_X" value="-0.070807"/>
    <xacro:property name="FEM_WJ_Y" value="0.02"/>
    <xacro:property name="FEM_WJ_Z" value="0.064307"/> -->
  <!-- FROM ORIGIN -->
  <!-- <xacro:macro name="FEM_MOTOR_WHEEL_JOINT_ORIGIN">
        <origin xyz="${FEM_WJ_X} ${FEM_WJ_Y} ${FEM_WJ_Z}" rpy="${PI_2} ${PI} 0" />
    </xacro:macro> -->
  <!-- ########################## END DOCK GENERATOR ############################ -->
  <!-- <xacro:include filename="$(find hexapod)/urdf/hexapod.gazebo" /> -->
  <!-- Footprint link -->
  <link name="base_footprint">
    <visual>
      <geometry>
        <cylinder length="0.001" radius="0.01"/>
      </geometry>
    </visual>
  </link>
  <!-- Floating-base Joint -->
  <!-- <joint name="floating_base" type="fixed">
        <origin xyz="0 0 0" rpy="0 0 0"/>
        <parent link="base_footprint"/>
        <child link="heaxpod_body_link"/>
    </joint> -->
  <!-- <xacro:generate_body/> -->
  <!-- ########################## BODY LINK ############################ -->
  <!-- Body link -->
  <link name="body_link">
    <collision>
      <geometry>
        <mesh filename="package://hexapod/urdf/models/baseWithCox.stl" scale="0.001 0.001 0.001"/>
      </geometry>
    </collision>
    <visual>
      <geometry>
        <mesh filename="package://hexapod/urdf/models/baseWithCox.stl" scale="0.001 0.001 0.001"/>
      </geometry>
    </visual>
    <inertial>
      <origin rpy="0 0 0" xyz="0 0 0"/>
      <mass value="0.1"/>
      <inertia ixx="0.02" ixy="0.0" ixz="0.0" iyy="0.02" iyz="0.0" izz="0.02"/>
      <!-- <inertia ixx="1.66666666667e-08" ixy="0.0" ixz="0.0"
                      iyy="1.66666666667e-08" iyz="0.0"
                      izz="1.66666666667e-08"/> -->
    </inertial>
  </link>
  <joint name="body_joint" type="fixed">
    <parent link="base_footprint"/>
    <child link="body_link"/>
  </joint>
  <gazebo reference="body_link">
    <mu1 value="10.0"/>
    <mu2 value="10.0"/>
    <kp value="10000.0"/>
    <kd value="10000.0"/>
    <material>Gazebo/Red</material>
  </gazebo>
  <link name="cox_motor_wheel_link">
    <collision>
      <geometry>
        <mesh filename="package://hexapod/urdf/models/ax12_wheel_faceOrigin.stl" scale="0.001 0.001 0.001"/>
      </geometry>
    </collision>
    <visual>
      <geometry>
        <mesh filename="package://hexapod/urdf/models/ax12_wheel_faceOrigin.stl" scale="0.001 0.001 0.001"/>
      </geometry>
    </visual>
    <inertial>
      <origin rpy="0 0 0" xyz="0 0 0"/>
      <mass value="0.1"/>
      <inertia ixx="0.02" ixy="0.0" ixz="0.0" iyy="0.02" iyz="0.0" izz="0.02"/>
      <!-- <inertia ixx="1.66666666667e-08" ixy="0.0" ixz="0.0"
                      iyy="1.66666666667e-08" iyz="0.0"
                      izz="1.66666666667e-08"/> -->
    </inertial>
  </link>
  <joint name="cox_motor_wheel_joint" type="revolute">
    <origin rpy="1.57079632679 3.14 0" xyz="-0.0635 0.0 0.003"/>
    <parent link="body_link"/>
    <child link="cox_motor_wheel_link"/>
    <axis rpy="0 0 0" xyz="0 1 0"/>
    <!-- <limit upper="${PI}" lower="${PI}" effort="10000" velocity="1000"/> -->
    <limit effort="1000.0" lower="-1.0" upper="1.0" velocity="0.5"/>
    <!-- <joint_properties damping="1.0" friction="1.0"/> -->
  </joint>
  <gazebo reference="cox_motor_wheel_link">
    <mu1 value="10.0"/>
    <mu2 value="10.0"/>
    <kp value="10000.0"/>
    <kd value="10000.0"/>
    <material>Gazebo/Green</material>
  </gazebo>
  <!-- ########################## TROCOX ############################ -->
  <link name="trocox_link">
    <collision>
      <geometry>
        <mesh filename="package://hexapod/urdf/models/trochanter_contactOrigin.stl" scale="0.001 0.001 0.001"/>
      </geometry>
    </collision>
    <visual>
      <geometry>
        <mesh filename="package://hexapod/urdf/models/trochanter_contactOrigin.stl" scale="0.001 0.001 0.001"/>
      </geometry>
    </visual>
    <inertial>
      <origin rpy="0 0 0" xyz="0 0 0"/>
      <mass value="0.1"/>
      <inertia ixx="0.02" ixy="0.0" ixz="0.0" iyy="0.02" iyz="0.0" izz="0.02"/>
      <!-- <inertia ixx="1.66666666667e-08" ixy="0.0" ixz="0.0"
                      iyy="1.66666666667e-08" iyz="0.0"
                      izz="1.66666666667e-08"/> -->
    </inertial>
  </link>
  <joint name="trocox_joint" type="fixed">
    <!-- <origin xyz="${TROCOX_X} ${TROCOX_Y} ${TROCOX_Z}" rpy="0 0 0" /> -->
    <origin rpy="3.14 0 0" xyz="0 0 0"/>
    <parent link="cox_motor_wheel_link"/>
    <child link="trocox_link"/>
    <!-- <axis xyz="0 0 1" rpy="0 0 0"/> -->
    <!-- <limit upper="${PI}" lower="${PI}" effort="10000" velocity="1000"/> -->
    <!-- <limit upper="1.0" lower="-1.0" effort="1000.0" velocity="0.5"/> -->
    <!-- <joint_properties damping="1.0" friction="1.0"/> -->
  </joint>
  <gazebo reference="trocox_link">
    <mu1 value="10.0"/>
    <mu2 value="10.0"/>
    <kp value="10000.0"/>
    <kd value="10000.0"/>
    <material>Gazebo/Red</material>
  </gazebo>
  <!-- <transmission name="${side}_dock_transmission">
            <type>transmission_interface/SimpleTransmission</type>
            <joint name="dock_${side}_joint"> -->
  <!-- <hardwareInterface>hardware_interface/EffortJointInterface</hardwareInterface> -->
  <!-- <hardwareInterface>EffortJointInterface</hardwareInterface>
            </joint>
            <actuator name="${side}_dock_actuator">
                <mechanicalReduction>7</mechanicalReduction>
                <hardwareInterface>EffortJointInterface</hardwareInterface>
            </actuator>
        </transmission> -->
  <!-- ########################## FEM WHEEL ############################ -->
  <link name="fem_motor_wheel_link">
    <origin rpy="-1.57079632679 0 -1.57079632679" xyz="0.007307 0.061307 -0.02 "/>
    <collision>
      <geometry>
        <mesh filename="package://hexapod/urdf/models/ax12_wheel_faceOrigin.stl" scale="0.001 0.001 0.001"/>
      </geometry>
    </collision>
    <visual>
      <geometry>
        <mesh filename="package://hexapod/urdf/models/ax12_wheel_faceOrigin.stl" scale="0.001 0.001 0.001"/>
      </geometry>
    </visual>
    <inertial>
      <origin rpy="0 0 0" xyz="0 0 0"/>
      <mass value="0.1"/>
      <inertia ixx="0.02" ixy="0.0" ixz="0.0" iyy="0.02" iyz="0.0" izz="0.02"/>
      <!-- <inertia ixx="1.66666666667e-08" ixy="0.0" ixz="0.0"
                      iyy="1.66666666667e-08" iyz="0.0"
                      izz="1.66666666667e-08"/> -->
    </inertial>
  </link>
  <joint name="fem_motor_wheel_joint" type="revolute">
    <origin rpy="-1.57079632679 0 -1.57079632679" xyz="0.007307 0.061307 -0.02 "/>
    <parent link="trocox_link"/>
    <child link="fem_motor_wheel_link"/>
    <axis rpy="0 0 0" xyz="0 1 0"/>
    <!-- <limit upper="${PI}" lower="${PI}" effort="10000" velocity="1000"/> -->
    <limit effort="1000.0" lower="-1.0" upper="1.0" velocity="0.5"/>
    <!-- <joint_properties damping="1.0" friction="1.0"/> -->
  </joint>
  <gazebo reference="fem_motor_wheel_link">
    <mu1 value="10.0"/>
    <mu2 value="10.0"/>
    <kp value="10000.0"/>
    <kd value="10000.0"/>
    <material>Gazebo/Blue</material>
  </gazebo>
  <!-- ########################## FEMUR ############################ -->
  <link name="femur_link">
    <collision>
      <geometry>
        <mesh filename="package://hexapod/urdf/models/femur_pPls.stl" scale="0.001 0.001 0.001"/>
      </geometry>
    </collision>
    <visual>
      <geometry>
        <mesh filename="package://hexapod/urdf/models/femur_pPls.stl" scale="0.001 0.001 0.001"/>
      </geometry>
    </visual>
    <inertial>
      <origin rpy="0 0 0" xyz="0 0 0"/>
      <mass value="0.1"/>
      <inertia ixx="0.02" ixy="0.0" ixz="0.0" iyy="0.02" iyz="0.0" izz="0.02"/>
      <!-- <inertia ixx="1.66666666667e-08" ixy="0.0" ixz="0.0"
                      iyy="1.66666666667e-08" iyz="0.0"
                      izz="1.66666666667e-08"/> -->
    </inertial>
  </link>
  <joint name="femur_joint" type="fixed">
    <origin rpy="0 -1.57079632679 0" xyz="0 -0.004 0"/>
    <parent link="fem_motor_wheel_link"/>
    <child link="femur_link"/>
  </joint>
  <gazebo reference="fem_motor_wheel_link">
    <mu1 value="10.0"/>
    <mu2 value="10.0"/>
    <kp value="10000.0"/>
    <kd value="10000.0"/>
    <material>Gazebo/Blue</material>
  </gazebo>
  <!-- <transmission name="${side}_dock_transmission">
            <type>transmission_interface/SimpleTransmission</type>
            <joint name="dock_${side}_joint"> -->
  <!-- <hardwareInterface>hardware_interface/EffortJointInterface</hardwareInterface> -->
  <!-- <hardwareInterface>EffortJointInterface</hardwareInterface>
            </joint>
            <actuator name="${side}_dock_actuator">
                <mechanicalReduction>7</mechanicalReduction>
                <hardwareInterface>EffortJointInterface</hardwareInterface>
            </actuator>
        </transmission> -->
  <!-- ########################## FEM WHEEL ############################ -->
  <link name="tib_motor_wheel_link">
    <origin rpy="0 0 0" xyz="0.032 0.004 0.0 "/>
    <collision>
      <geometry>
        <mesh filename="package://hexapod/urdf/models/ax12_wheel_faceOrigin.stl" scale="0.001 0.001 0.001"/>
      </geometry>
    </collision>
    <visual>
      <geometry>
        <mesh filename="package://hexapod/urdf/models/ax12_wheel_faceOrigin.stl" scale="0.001 0.001 0.001"/>
      </geometry>
    </visual>
    <inertial>
      <origin rpy="0 0 0" xyz="0 0 0"/>
      <mass value="0.1"/>
      <inertia ixx="0.02" ixy="0.0" ixz="0.0" iyy="0.02" iyz="0.0" izz="0.02"/>
      <!-- <inertia ixx="1.66666666667e-08" ixy="0.0" ixz="0.0"
                      iyy="1.66666666667e-08" iyz="0.0"
                      izz="1.66666666667e-08"/> -->
    </inertial>
  </link>
  <joint name="tib_motor_wheel_joint" type="revolute">
    <origin rpy="0 0 0" xyz="0.032 0.004 0.0 "/>
    <parent link="femur_link"/>
    <child link="tib_motor_wheel_link"/>
    <axis rpy="0 0 0" xyz="0 1 0"/>
    <!-- <limit upper="${PI}" lower="${PI}" effort="10000" velocity="1000"/> -->
    <limit effort="1000.0" lower="-1.0" upper="1.0" velocity="0.5"/>
    <!-- <joint_properties damping="1.0" friction="1.0"/> -->
  </joint>
  <gazebo reference="tib_motor_wheel_link">
    <mu1 value="10.0"/>
    <mu2 value="10.0"/>
    <kp value="10000.0"/>
    <kd value="10000.0"/>
    <material>Gazebo/Blue</material>
  </gazebo>
  <!-- ########################## TIBIA ############################ -->
  <link name="tibia_link">
    <collision>
      <geometry>
        <mesh filename="package://hexapod/urdf/models/tib3piece_centered.stl" scale="0.001 0.001 0.001"/>
      </geometry>
    </collision>
    <visual>
      <geometry>
        <mesh filename="package://hexapod/urdf/models/tib3piece_centered.stl" scale="0.001 0.001 0.001"/>
      </geometry>
    </visual>
    <inertial>
      <origin rpy="0 0 0" xyz="0 0 0"/>
      <mass value="0.1"/>
      <inertia ixx="0.02" ixy="0.0" ixz="0.0" iyy="0.02" iyz="0.0" izz="0.02"/>
      <!-- <inertia ixx="1.66666666667e-08" ixy="0.0" ixz="0.0"
                      iyy="1.66666666667e-08" iyz="0.0"
                      izz="1.66666666667e-08"/> -->
    </inertial>
  </link>
  <joint name="tibia_joint" type="fixed">
    <origin rpy="0 0 -3.14" xyz="0.0 -0.019924 -0.01826"/>
    <parent link="tib_motor_wheel_link"/>
    <child link="tibia_link"/>
  </joint>
  <gazebo reference="tibia_link">
    <mu1 value="10.0"/>
    <mu2 value="10.0"/>
    <kp value="10000.0"/>
    <kd value="10000.0"/>
    <material>Gazebo/Blue</material>
  </gazebo>
  <!-- <transmission name="${side}_dock_transmission">
            <type>transmission_interface/SimpleTransmission</type>
            <joint name="dock_${side}_joint"> -->
  <!-- <hardwareInterface>hardware_interface/EffortJointInterface</hardwareInterface> -->
  <!-- <hardwareInterface>EffortJointInterface</hardwareInterface>
            </joint>
            <actuator name="${side}_dock_actuator">
                <mechanicalReduction>7</mechanicalReduction>
                <hardwareInterface>EffortJointInterface</hardwareInterface>
            </actuator>
        </transmission> -->
</robot>

