<?xml version="1.0" encoding="utf-8"?>
<!-- =================================================================================== -->
<!-- |    This document was autogenerated by xacro from hexapod.urdf.xacro             | -->
<!-- |    EDITING THIS FILE BY HAND IS NOT RECOMMENDED                                 | -->
<!-- =================================================================================== -->
<robot name="hexapod">
  <!-- Dynamic contact stiffness. This determines if the link material is closer to marble (very rigid, bigger values) or more like rubber (soft material, lower values). It's essentially how much it deforms over a long period of time, exerting its pressure. -->
  <!-- ################################################################## -->
  <!-- ########################## GENERATORS ############################ -->
  <!-- ################################################################## -->
  <!-- ########################## END INERTIA GENERATOR ############################ -->
  <!-- ################################################################## -->
  <!-- ############################ COLORS ############################## -->
  <!-- ################################################################## -->
  <!-- These are for URDF coloring. Gazebo colors begin with capital letters -->
  <material name="blue">
    <color rgba="0.0 0.0 0.8 1.0"/>
  </material>
  <material name="green">
    <color rgba="0.0 0.8 0.0 1.0"/>
  </material>
  <material name="grey">
    <color rgba="0.7 0.7 0.7 1.0"/>
  </material>
  <material name="lightGrey">
    <color rgba="0.9 0.9 0.9 1.0"/>
  </material>
  <material name="darkGrey">
    <color rgba="0.2 0.2 0.2 1.0"/>
  </material>
  <material name="red">
    <color rgba="0.8 0.0 0.0 1.0"/>
  </material>
  <material name="white">
    <color rgba="1.0 1.0 1.0 1.0"/>
  </material>
  <material name="orange">
    <color rgba="1.0 0.69 0.0 1.0"/>
  </material>
  <!--body mass: 1.503462, Total Mass: 2.812273-->
  <!-- ########################## END HEX GENERATOR ############################ -->
  <!-- <xacro:include filename="$(find hexapod)/urdf/general.urdf.xacro"/> -->
  <!-- <xacro:macro name="get_origin" params="side position joint_type"> -->
  <!-- <xacro:property name="coords" value="${origins['${side}_${position}_${joint_type}']}"/> -->
  <!-- </xacro:macro> -->
  <!-- <xacro:property name="mapping" value="${None}"/> -->
  <!-- <xacro:property name="mapping" value="${mapping.get('handedness','right')}"/> -->
  <!-- <xacro:property name="proximal_len" value="${properties['link_lengths'][finger]['proximal']}"/> -->
  <!-- ########################## END COXA GENERATOR ############################ -->
  <!-- ########################## END DOCK GENERATOR ############################ -->
  <!-- ########################## END HEXAPOD LEG GENERATOR ############################ -->
  <!-- <xacro:include filename="$(find hexapod)/urdf/hexapod.gazebo" /> -->
  <!-- Footprint link -->
  <link name="base_footprint">
    <visual>
      <geometry>
        <cylinder length="0.001" radius="0.01"/>
      </geometry>
    </visual>
  </link>
  <!-- Floating-base Joint -->
  <!-- <joint name="floating_base" type="fixed">
        <origin xyz="0 0 0" rpy="0 0 0"/>
        <parent link="base_footprint"/>
        <child link="heaxpod_body_link"/>
    </joint> -->
  <!-- <xacro:generate_body/> -->
  <!-- ########################## BODY LINK ############################ -->
  <!-- Body link -->
  <link name="body_link">
    <collision>
      <geometry>
        <mesh filename="package://hexapod/urdf/models/base.stl" scale="0.001 0.001 0.001"/>
      </geometry>
    </collision>
    <visual>
      <geometry>
        <mesh filename="package://hexapod/urdf/models/base.stl" scale="0.001 0.001 0.001"/>
      </geometry>
    </visual>
    <inertial>
      <origin rpy="0 0 0" xyz="0 0 0"/>
      <mass value="0.1"/>
      <inertia ixx="0.02" ixy="0.0" ixz="0.0" iyy="0.02" iyz="0.0" izz="0.02"/>
      <!-- <inertia ixx="1.66666666667e-08" ixy="0.0" ixz="0.0"
                      iyy="1.66666666667e-08" iyz="0.0"
                      izz="1.66666666667e-08"/> -->
    </inertial>
  </link>
  <joint name="body_joint" type="fixed">
    <parent link="base_footprint"/>
    <child link="body_link"/>
  </joint>
  <gazebo reference="body_link">
    <mu1 value="10.0"/>
    <mu2 value="10.0"/>
    <kp value="10000.0"/>
    <kd value="10000.0"/>
    <material>Gazebo/Red</material>
  </gazebo>
  <link name="R_M_COX_link">
    <collision>
      <geometry>
        <mesh filename="package://hexapod/urdf/models/coxa_R_M.stl" scale="0.001 0.001 0.001"/>
      </geometry>
    </collision>
    <visual>
      <geometry>
        <mesh filename="package://hexapod/urdf/models/coxa_R_M.stl" scale="0.001 0.001 0.001"/>
      </geometry>
    </visual>
    <inertial>
      <!-- <origin xyz="0 0 0" rpy="0 0 0" /> -->
      <mass value="0.02769"/>
      <inertia ixx="4.45078267e-05" ixy="2.313093757e-06" ixz="5.691000762e-05" iyy="0.0001480260304" iyz="-2.102291688e-06" izz="0.0001110195228"/>
    </inertial>
  </link>
  <joint name="R_M_COX_joint" type="revolute">
    <origin rpy="0 0 0" xyz="-0.0635 0 0.007"/>
    <parent link="body_link"/>
    <child link="R_M_COX_link"/>
    <axis rpy="0 0 0" xyz="0 0 1"/>
    <!-- <limit upper="${PI}" lower="${PI}" effort="10000" velocity="1000"/> -->
    <limit effort="1000.0" lower="-1.0" upper="1.0" velocity="0.5"/>
    <!-- <joint_properties damping="1.0" friction="1.0"/> -->
  </joint>
  <gazebo reference="R_M_COX_link">
    <mu1 value="10.0"/>
    <mu2 value="10.0"/>
    <kp value="10000.0"/>
    <kd value="10000.0"/>
    <material>Gazebo/Green</material>
  </gazebo>
  <link name="R_M_FEM_link">
    <collision>
      <geometry>
        <mesh filename="package://hexapod/urdf/models/femur_R_M.stl" scale="0.001 0.001 0.001"/>
      </geometry>
    </collision>
    <visual>
      <geometry>
        <mesh filename="package://hexapod/urdf/models/femur_R_M.stl" scale="0.001 0.001 0.001"/>
      </geometry>
    </visual>
    <inertial>
      <!-- <origin xyz="0 0 0" rpy="0 0 0" /> -->
      <mass value="0.02769"/>
      <inertia ixx="4.45078267e-05" ixy="2.313093757e-06" ixz="5.691000762e-05" iyy="0.0001480260304" iyz="-2.102291688e-06" izz="0.0001110195228"/>
    </inertial>
  </link>
  <joint name="R_M_FEM_joint" type="revolute">
    <origin rpy="0 0 0" xyz="-0.007261 0.015954 0.057284"/>
    <parent link="R_M_COX_link"/>
    <child link="R_M_FEM_link"/>
    <axis rpy="0 0 0" xyz="0 1 0"/>
    <!-- <limit upper="${PI}" lower="${PI}" effort="10000" velocity="1000"/> -->
    <limit effort="1000.0" lower="-1.0" upper="1.0" velocity="0.5"/>
    <!-- <joint_properties damping="1.0" friction="1.0"/> -->
  </joint>
  <gazebo reference="R_M_FEM_link">
    <mu1 value="10.0"/>
    <mu2 value="10.0"/>
    <kp value="10000.0"/>
    <kd value="10000.0"/>
    <material>Gazebo/Blue</material>
  </gazebo>
  <!-- <transmission name="${side}_dock_transmission">
            <type>transmission_interface/SimpleTransmission</type>
            <joint name="dock_${side}_joint"> -->
  <!-- <hardwareInterface>hardware_interface/EffortJointInterface</hardwareInterface> -->
  <!-- <hardwareInterface>EffortJointInterface</hardwareInterface>
            </joint>
            <actuator name="${side}_dock_actuator">
                <mechanicalReduction>7</mechanicalReduction>
                <hardwareInterface>EffortJointInterface</hardwareInterface>
            </actuator>
        </transmission> -->
  <link name="R_M_TIB_link">
    <collision>
      <geometry>
        <mesh filename="package://hexapod/urdf/models/tibia_R_M.stl" scale="0.001 0.001 0.001"/>
      </geometry>
    </collision>
    <visual>
      <geometry>
        <mesh filename="package://hexapod/urdf/models/tibia_R_M.stl" scale="0.001 0.001 0.001"/>
      </geometry>
    </visual>
    <inertial>
      <origin rpy="0 0 0" xyz="0 0 0"/>
      <mass value="0.1"/>
      <inertia ixx="0.02" ixy="0.0" ixz="0.0" iyy="0.02" iyz="0.0" izz="0.02"/>
      <!-- <inertia ixx="1.66666666667e-08" ixy="0.0" ixz="0.0"
                      iyy="1.66666666667e-08" iyz="0.0"
                      izz="1.66666666667e-08"/> -->
    </inertial>
  </link>
  <link name="R_M_TIB_link">
    <collision>
      <geometry>
        <mesh filename="package://hexapod/urdf/models/tibia_R_M.stl" scale="0.001 0.001 0.001"/>
      </geometry>
    </collision>
    <visual>
      <geometry>
        <mesh filename="package://hexapod/urdf/models/tibia_R_M.stl" scale="0.001 0.001 0.001"/>
      </geometry>
    </visual>
    <inertial>
      <!-- <origin xyz="0 0 0" rpy="0 0 0" /> -->
      <mass value="0.02769"/>
      <inertia ixx="4.45078267e-05" ixy="2.313093757e-06" ixz="5.691000762e-05" iyy="0.0001480260304" iyz="-2.102291688e-06" izz="0.0001110195228"/>
    </inertial>
  </link>
  <joint name="R_M_TIB_joint" type="revolute">
    <origin rpy="0 0 0" xyz="-0.032 0 0"/>
    <parent link="R_M_FEM_link"/>
    <child link="R_M_TIB_link"/>
    <axis rpy="0 0 0" xyz="0 1 0"/>
    <!-- <limit upper="${PI}" lower="${PI}" effort="10000" velocity="1000"/> -->
    <limit effort="1000.0" lower="-1.0" upper="1.0" velocity="0.5"/>
    <!-- <joint_properties damping="1.0" friction="1.0"/> -->
  </joint>
  <gazebo reference="R_M_TIB_link">
    <mu1 value="10.0"/>
    <mu2 value="10.0"/>
    <kp value="10000.0"/>
    <kd value="10000.0"/>
    <material>Gazebo/Green</material>
  </gazebo>
  <link name="R_F_COX_link">
    <collision>
      <geometry>
        <mesh filename="package://hexapod/urdf/models/coxa_R_F.stl" scale="0.001 0.001 0.001"/>
      </geometry>
    </collision>
    <visual>
      <geometry>
        <mesh filename="package://hexapod/urdf/models/coxa_R_F.stl" scale="0.001 0.001 0.001"/>
      </geometry>
    </visual>
    <inertial>
      <!-- <origin xyz="0 0 0" rpy="0 0 0" /> -->
      <mass value="0.02769"/>
      <inertia ixx="0.0001500263821" ixy="-9.271630416e-05" ixz="4.990877646e-05" iyy="0.0001250219851" iyz="5.781016591e-05" izz="0.0001940341209"/>
    </inertial>
  </link>
  <joint name="R_F_COX_joint" type="revolute">
    <origin rpy="0 0 0" xyz="-0.057077 -0.066312 0.007"/>
    <parent link="body_link"/>
    <child link="R_F_COX_link"/>
    <axis rpy="0 0 0" xyz="0 0 1"/>
    <!-- <limit upper="${PI}" lower="${PI}" effort="10000" velocity="1000"/> -->
    <limit effort="1000.0" lower="-1.0" upper="1.0" velocity="0.5"/>
    <!-- <joint_properties damping="1.0" friction="1.0"/> -->
  </joint>
  <gazebo reference="R_F_COX_link">
    <mu1 value="10.0"/>
    <mu2 value="10.0"/>
    <kp value="10000.0"/>
    <kd value="10000.0"/>
    <material>Gazebo/Green</material>
  </gazebo>
  <link name="R_F_FEM_link">
    <collision>
      <geometry>
        <mesh filename="package://hexapod/urdf/models/femur_R_F.stl" scale="0.001 0.001 0.001"/>
      </geometry>
    </collision>
    <visual>
      <geometry>
        <mesh filename="package://hexapod/urdf/models/femur_R_F.stl" scale="0.001 0.001 0.001"/>
      </geometry>
    </visual>
    <inertial>
      <!-- <origin xyz="0 0 0" rpy="0 0 0" /> -->
      <mass value="0.02769"/>
      <inertia ixx="0.0001500263821" ixy="-9.271630416e-05" ixz="4.990877646e-05" iyy="0.0001250219851" iyz="5.781016591e-05" izz="0.0001940341209"/>
    </inertial>
  </link>
  <joint name="R_F_FEM_joint" type="revolute">
    <origin rpy="0 0 0" xyz="-0.007261 -0.017448 0.057284"/>
    <parent link="R_F_COX_link"/>
    <child link="R_F_FEM_link"/>
    <axis rpy="0 0 0" xyz="0 1 0"/>
    <!-- <limit upper="${PI}" lower="${PI}" effort="10000" velocity="1000"/> -->
    <limit effort="1000.0" lower="-1.0" upper="1.0" velocity="0.5"/>
    <!-- <joint_properties damping="1.0" friction="1.0"/> -->
  </joint>
  <gazebo reference="R_F_FEM_link">
    <mu1 value="10.0"/>
    <mu2 value="10.0"/>
    <kp value="10000.0"/>
    <kd value="10000.0"/>
    <material>Gazebo/Blue</material>
  </gazebo>
  <!-- <transmission name="${side}_dock_transmission">
            <type>transmission_interface/SimpleTransmission</type>
            <joint name="dock_${side}_joint"> -->
  <!-- <hardwareInterface>hardware_interface/EffortJointInterface</hardwareInterface> -->
  <!-- <hardwareInterface>EffortJointInterface</hardwareInterface>
            </joint>
            <actuator name="${side}_dock_actuator">
                <mechanicalReduction>7</mechanicalReduction>
                <hardwareInterface>EffortJointInterface</hardwareInterface>
            </actuator>
        </transmission> -->
  <link name="R_F_TIB_link">
    <collision>
      <geometry>
        <mesh filename="package://hexapod/urdf/models/tibia_R_F.stl" scale="0.001 0.001 0.001"/>
      </geometry>
    </collision>
    <visual>
      <geometry>
        <mesh filename="package://hexapod/urdf/models/tibia_R_F.stl" scale="0.001 0.001 0.001"/>
      </geometry>
    </visual>
    <inertial>
      <origin rpy="0 0 0" xyz="0 0 0"/>
      <mass value="0.1"/>
      <inertia ixx="0.02" ixy="0.0" ixz="0.0" iyy="0.02" iyz="0.0" izz="0.02"/>
      <!-- <inertia ixx="1.66666666667e-08" ixy="0.0" ixz="0.0"
                      iyy="1.66666666667e-08" iyz="0.0"
                      izz="1.66666666667e-08"/> -->
    </inertial>
  </link>
  <link name="R_F_TIB_link">
    <collision>
      <geometry>
        <mesh filename="package://hexapod/urdf/models/tibia_R_F.stl" scale="0.001 0.001 0.001"/>
      </geometry>
    </collision>
    <visual>
      <geometry>
        <mesh filename="package://hexapod/urdf/models/tibia_R_F.stl" scale="0.001 0.001 0.001"/>
      </geometry>
    </visual>
    <inertial>
      <!-- <origin xyz="0 0 0" rpy="0 0 0" /> -->
      <mass value="0.02769"/>
      <inertia ixx="0.0001500263821" ixy="-9.271630416e-05" ixz="4.990877646e-05" iyy="0.0001250219851" iyz="5.781016591e-05" izz="0.0001940341209"/>
    </inertial>
  </link>
  <joint name="R_F_TIB_joint" type="revolute">
    <origin rpy="0 0 0" xyz="-0.027712 0 0"/>
    <parent link="R_F_FEM_link"/>
    <child link="R_F_TIB_link"/>
    <axis rpy="0 0 0" xyz="0 1 0"/>
    <!-- <limit upper="${PI}" lower="${PI}" effort="10000" velocity="1000"/> -->
    <limit effort="1000.0" lower="-1.0" upper="1.0" velocity="0.5"/>
    <!-- <joint_properties damping="1.0" friction="1.0"/> -->
  </joint>
  <gazebo reference="R_F_TIB_link">
    <mu1 value="10.0"/>
    <mu2 value="10.0"/>
    <kp value="10000.0"/>
    <kd value="10000.0"/>
    <material>Gazebo/Green</material>
  </gazebo>
  <link name="R_B_COX_link">
    <collision>
      <geometry>
        <mesh filename="package://hexapod/urdf/models/coxa_R_B.stl" scale="0.001 0.001 0.001"/>
      </geometry>
    </collision>
    <visual>
      <geometry>
        <mesh filename="package://hexapod/urdf/models/coxa_R_B.stl" scale="0.001 0.001 0.001"/>
      </geometry>
    </visual>
    <inertial>
      <!-- <origin xyz="0 0 0" rpy="0 0 0" /> -->
      <mass value="0.02769"/>
      <inertia ixx="0.0001500263821" ixy="9.271630416e-05" ixz="4.990877646e-05" iyy="0.0001250219851" iyz="-5.781016591e-05" izz="0.0001940341209"/>
    </inertial>
  </link>
  <joint name="R_B_COX_joint" type="revolute">
    <origin rpy="0 0 0" xyz="-0.057077 0.066312 0.007"/>
    <parent link="body_link"/>
    <child link="R_B_COX_link"/>
    <axis rpy="0 0 0" xyz="0 0 1"/>
    <!-- <limit upper="${PI}" lower="${PI}" effort="10000" velocity="1000"/> -->
    <limit effort="1000.0" lower="-1.0" upper="1.0" velocity="0.5"/>
    <!-- <joint_properties damping="1.0" friction="1.0"/> -->
  </joint>
  <gazebo reference="R_B_COX_link">
    <mu1 value="10.0"/>
    <mu2 value="10.0"/>
    <kp value="10000.0"/>
    <kd value="10000.0"/>
    <material>Gazebo/Green</material>
  </gazebo>
  <link name="R_B_FEM_link">
    <collision>
      <geometry>
        <mesh filename="package://hexapod/urdf/models/femur_R_B.stl" scale="0.001 0.001 0.001"/>
      </geometry>
    </collision>
    <visual>
      <geometry>
        <mesh filename="package://hexapod/urdf/models/femur_R_B.stl" scale="0.001 0.001 0.001"/>
      </geometry>
    </visual>
    <inertial>
      <!-- <origin xyz="0 0 0" rpy="0 0 0" /> -->
      <mass value="0.02769"/>
      <inertia ixx="0.0001500263821" ixy="9.271630416e-05" ixz="4.990877646e-05" iyy="0.0001250219851" iyz="-5.781016591e-05" izz="0.0001940341209"/>
    </inertial>
  </link>
  <joint name="R_B_FEM_joint" type="revolute">
    <origin rpy="0 0 0" xyz="-0.007261 0.017438 0.057284"/>
    <parent link="R_B_COX_link"/>
    <child link="R_B_FEM_link"/>
    <axis rpy="0 0 0" xyz="0 1 0"/>
    <!-- <limit upper="${PI}" lower="${PI}" effort="10000" velocity="1000"/> -->
    <limit effort="1000.0" lower="-1.0" upper="1.0" velocity="0.5"/>
    <!-- <joint_properties damping="1.0" friction="1.0"/> -->
  </joint>
  <gazebo reference="R_B_FEM_link">
    <mu1 value="10.0"/>
    <mu2 value="10.0"/>
    <kp value="10000.0"/>
    <kd value="10000.0"/>
    <material>Gazebo/Blue</material>
  </gazebo>
  <!-- <transmission name="${side}_dock_transmission">
            <type>transmission_interface/SimpleTransmission</type>
            <joint name="dock_${side}_joint"> -->
  <!-- <hardwareInterface>hardware_interface/EffortJointInterface</hardwareInterface> -->
  <!-- <hardwareInterface>EffortJointInterface</hardwareInterface>
            </joint>
            <actuator name="${side}_dock_actuator">
                <mechanicalReduction>7</mechanicalReduction>
                <hardwareInterface>EffortJointInterface</hardwareInterface>
            </actuator>
        </transmission> -->
  <link name="R_B_TIB_link">
    <collision>
      <geometry>
        <mesh filename="package://hexapod/urdf/models/tibia_R_B.stl" scale="0.001 0.001 0.001"/>
      </geometry>
    </collision>
    <visual>
      <geometry>
        <mesh filename="package://hexapod/urdf/models/tibia_R_B.stl" scale="0.001 0.001 0.001"/>
      </geometry>
    </visual>
    <inertial>
      <origin rpy="0 0 0" xyz="0 0 0"/>
      <mass value="0.1"/>
      <inertia ixx="0.02" ixy="0.0" ixz="0.0" iyy="0.02" iyz="0.0" izz="0.02"/>
      <!-- <inertia ixx="1.66666666667e-08" ixy="0.0" ixz="0.0"
                      iyy="1.66666666667e-08" iyz="0.0"
                      izz="1.66666666667e-08"/> -->
    </inertial>
  </link>
  <link name="R_B_TIB_link">
    <collision>
      <geometry>
        <mesh filename="package://hexapod/urdf/models/tibia_R_B.stl" scale="0.001 0.001 0.001"/>
      </geometry>
    </collision>
    <visual>
      <geometry>
        <mesh filename="package://hexapod/urdf/models/tibia_R_B.stl" scale="0.001 0.001 0.001"/>
      </geometry>
    </visual>
    <inertial>
      <!-- <origin xyz="0 0 0" rpy="0 0 0" /> -->
      <mass value="0.02769"/>
      <inertia ixx="0.0001500263821" ixy="9.271630416e-05" ixz="4.990877646e-05" iyy="0.0001250219851" iyz="-5.781016591e-05" izz="0.0001940341209"/>
    </inertial>
  </link>
  <joint name="R_B_TIB_joint" type="revolute">
    <origin rpy="0 0 0" xyz="-0.027712 0 0"/>
    <parent link="R_B_FEM_link"/>
    <child link="R_B_TIB_link"/>
    <axis rpy="0 0 0" xyz="0 1 0"/>
    <!-- <limit upper="${PI}" lower="${PI}" effort="10000" velocity="1000"/> -->
    <limit effort="1000.0" lower="-1.0" upper="1.0" velocity="0.5"/>
    <!-- <joint_properties damping="1.0" friction="1.0"/> -->
  </joint>
  <gazebo reference="R_B_TIB_link">
    <mu1 value="10.0"/>
    <mu2 value="10.0"/>
    <kp value="10000.0"/>
    <kd value="10000.0"/>
    <material>Gazebo/Green</material>
  </gazebo>
  <link name="L_M_COX_link">
    <collision>
      <geometry>
        <mesh filename="package://hexapod/urdf/models/coxa_L_M.stl" scale="0.001 0.001 0.001"/>
      </geometry>
    </collision>
    <visual>
      <geometry>
        <mesh filename="package://hexapod/urdf/models/coxa_L_M.stl" scale="0.001 0.001 0.001"/>
      </geometry>
    </visual>
    <inertial>
      <!-- <origin xyz="0 0 0" rpy="0 0 0" /> -->
      <mass value="0.02769"/>
      <inertia ixx="4.45078267e-05" ixy="-2.313098758e-06" ixz="-5.691000762e-05" iyy="0.0001480260304" iyz="-2.102295689e-06" izz="0.0001110195228"/>
    </inertial>
  </link>
  <joint name="L_M_COX_joint" type="revolute">
    <origin rpy="0 0 0" xyz="0.0635 0 0.007"/>
    <parent link="body_link"/>
    <child link="L_M_COX_link"/>
    <axis rpy="0 0 0" xyz="0 0 1"/>
    <!-- <limit upper="${PI}" lower="${PI}" effort="10000" velocity="1000"/> -->
    <limit effort="1000.0" lower="-1.0" upper="1.0" velocity="0.5"/>
    <!-- <joint_properties damping="1.0" friction="1.0"/> -->
  </joint>
  <gazebo reference="L_M_COX_link">
    <mu1 value="10.0"/>
    <mu2 value="10.0"/>
    <kp value="10000.0"/>
    <kd value="10000.0"/>
    <material>Gazebo/Green</material>
  </gazebo>
  <link name="L_M_FEM_link">
    <collision>
      <geometry>
        <mesh filename="package://hexapod/urdf/models/femur_L_M.stl" scale="0.001 0.001 0.001"/>
      </geometry>
    </collision>
    <visual>
      <geometry>
        <mesh filename="package://hexapod/urdf/models/femur_L_M.stl" scale="0.001 0.001 0.001"/>
      </geometry>
    </visual>
    <inertial>
      <!-- <origin xyz="0 0 0" rpy="0 0 0" /> -->
      <mass value="0.02769"/>
      <inertia ixx="4.45078267e-05" ixy="-2.313098758e-06" ixz="-5.691000762e-05" iyy="0.0001480260304" iyz="-2.102295689e-06" izz="0.0001110195228"/>
    </inertial>
  </link>
  <joint name="L_M_FEM_joint" type="revolute">
    <origin rpy="0 0 0" xyz="0.007261 0.015954 0.057284"/>
    <parent link="L_M_COX_link"/>
    <child link="L_M_FEM_link"/>
    <axis rpy="0 0 0" xyz="0 1 0"/>
    <!-- <limit upper="${PI}" lower="${PI}" effort="10000" velocity="1000"/> -->
    <limit effort="1000.0" lower="-1.0" upper="1.0" velocity="0.5"/>
    <!-- <joint_properties damping="1.0" friction="1.0"/> -->
  </joint>
  <gazebo reference="L_M_FEM_link">
    <mu1 value="10.0"/>
    <mu2 value="10.0"/>
    <kp value="10000.0"/>
    <kd value="10000.0"/>
    <material>Gazebo/Blue</material>
  </gazebo>
  <!-- <transmission name="${side}_dock_transmission">
            <type>transmission_interface/SimpleTransmission</type>
            <joint name="dock_${side}_joint"> -->
  <!-- <hardwareInterface>hardware_interface/EffortJointInterface</hardwareInterface> -->
  <!-- <hardwareInterface>EffortJointInterface</hardwareInterface>
            </joint>
            <actuator name="${side}_dock_actuator">
                <mechanicalReduction>7</mechanicalReduction>
                <hardwareInterface>EffortJointInterface</hardwareInterface>
            </actuator>
        </transmission> -->
  <link name="L_M_TIB_link">
    <collision>
      <geometry>
        <mesh filename="package://hexapod/urdf/models/tibia_L_M.stl" scale="0.001 0.001 0.001"/>
      </geometry>
    </collision>
    <visual>
      <geometry>
        <mesh filename="package://hexapod/urdf/models/tibia_L_M.stl" scale="0.001 0.001 0.001"/>
      </geometry>
    </visual>
    <inertial>
      <origin rpy="0 0 0" xyz="0 0 0"/>
      <mass value="0.1"/>
      <inertia ixx="0.02" ixy="0.0" ixz="0.0" iyy="0.02" iyz="0.0" izz="0.02"/>
      <!-- <inertia ixx="1.66666666667e-08" ixy="0.0" ixz="0.0"
                      iyy="1.66666666667e-08" iyz="0.0"
                      izz="1.66666666667e-08"/> -->
    </inertial>
  </link>
  <link name="L_M_TIB_link">
    <collision>
      <geometry>
        <mesh filename="package://hexapod/urdf/models/tibia_L_M.stl" scale="0.001 0.001 0.001"/>
      </geometry>
    </collision>
    <visual>
      <geometry>
        <mesh filename="package://hexapod/urdf/models/tibia_L_M.stl" scale="0.001 0.001 0.001"/>
      </geometry>
    </visual>
    <inertial>
      <!-- <origin xyz="0 0 0" rpy="0 0 0" /> -->
      <mass value="0.02769"/>
      <inertia ixx="4.45078267e-05" ixy="-2.313098758e-06" ixz="-5.691000762e-05" iyy="0.0001480260304" iyz="-2.102295689e-06" izz="0.0001110195228"/>
    </inertial>
  </link>
  <joint name="L_M_TIB_joint" type="revolute">
    <origin rpy="0 0 0" xyz="0.032 0 0"/>
    <parent link="L_M_FEM_link"/>
    <child link="L_M_TIB_link"/>
    <axis rpy="0 0 0" xyz="0 1 0"/>
    <!-- <limit upper="${PI}" lower="${PI}" effort="10000" velocity="1000"/> -->
    <limit effort="1000.0" lower="-1.0" upper="1.0" velocity="0.5"/>
    <!-- <joint_properties damping="1.0" friction="1.0"/> -->
  </joint>
  <gazebo reference="L_M_TIB_link">
    <mu1 value="10.0"/>
    <mu2 value="10.0"/>
    <kp value="10000.0"/>
    <kd value="10000.0"/>
    <material>Gazebo/Green</material>
  </gazebo>
  <link name="L_F_COX_link">
    <collision>
      <geometry>
        <mesh filename="package://hexapod/urdf/models/coxa_L_F.stl" scale="0.001 0.001 0.001"/>
      </geometry>
    </collision>
    <visual>
      <geometry>
        <mesh filename="package://hexapod/urdf/models/coxa_L_F.stl" scale="0.001 0.001 0.001"/>
      </geometry>
    </visual>
    <inertial>
      <!-- <origin xyz="0 0 0" rpy="0 0 0" /> -->
      <mass value="0.02769"/>
      <inertia ixx="0.0001500263821" ixy="9.271630416e-05" ixz="-4.990877646e-05" iyy="0.0001250219851" iyz="5.781016591e-05" izz="0.0001940341209"/>
    </inertial>
  </link>
  <joint name="L_F_COX_joint" type="revolute">
    <origin rpy="0 0 0" xyz="0.057077 -0.066312 0.007"/>
    <parent link="body_link"/>
    <child link="L_F_COX_link"/>
    <axis rpy="0 0 0" xyz="0 0 1"/>
    <!-- <limit upper="${PI}" lower="${PI}" effort="10000" velocity="1000"/> -->
    <limit effort="1000.0" lower="-1.0" upper="1.0" velocity="0.5"/>
    <!-- <joint_properties damping="1.0" friction="1.0"/> -->
  </joint>
  <gazebo reference="L_F_COX_link">
    <mu1 value="10.0"/>
    <mu2 value="10.0"/>
    <kp value="10000.0"/>
    <kd value="10000.0"/>
    <material>Gazebo/Green</material>
  </gazebo>
  <link name="L_F_FEM_link">
    <collision>
      <geometry>
        <mesh filename="package://hexapod/urdf/models/femur_L_F.stl" scale="0.001 0.001 0.001"/>
      </geometry>
    </collision>
    <visual>
      <geometry>
        <mesh filename="package://hexapod/urdf/models/femur_L_F.stl" scale="0.001 0.001 0.001"/>
      </geometry>
    </visual>
    <inertial>
      <!-- <origin xyz="0 0 0" rpy="0 0 0" /> -->
      <mass value="0.02769"/>
      <inertia ixx="0.0001500263821" ixy="9.271630416e-05" ixz="-4.990877646e-05" iyy="0.0001250219851" iyz="5.781016591e-05" izz="0.0001940341209"/>
    </inertial>
  </link>
  <joint name="L_F_FEM_joint" type="revolute">
    <origin rpy="0 0 0" xyz="0.007261 -0.017448 0.057284"/>
    <parent link="L_F_COX_link"/>
    <child link="L_F_FEM_link"/>
    <axis rpy="0 0 0" xyz="0 1 0"/>
    <!-- <limit upper="${PI}" lower="${PI}" effort="10000" velocity="1000"/> -->
    <limit effort="1000.0" lower="-1.0" upper="1.0" velocity="0.5"/>
    <!-- <joint_properties damping="1.0" friction="1.0"/> -->
  </joint>
  <gazebo reference="L_F_FEM_link">
    <mu1 value="10.0"/>
    <mu2 value="10.0"/>
    <kp value="10000.0"/>
    <kd value="10000.0"/>
    <material>Gazebo/Blue</material>
  </gazebo>
  <!-- <transmission name="${side}_dock_transmission">
            <type>transmission_interface/SimpleTransmission</type>
            <joint name="dock_${side}_joint"> -->
  <!-- <hardwareInterface>hardware_interface/EffortJointInterface</hardwareInterface> -->
  <!-- <hardwareInterface>EffortJointInterface</hardwareInterface>
            </joint>
            <actuator name="${side}_dock_actuator">
                <mechanicalReduction>7</mechanicalReduction>
                <hardwareInterface>EffortJointInterface</hardwareInterface>
            </actuator>
        </transmission> -->
  <link name="L_F_TIB_link">
    <collision>
      <geometry>
        <mesh filename="package://hexapod/urdf/models/tibia_L_F.stl" scale="0.001 0.001 0.001"/>
      </geometry>
    </collision>
    <visual>
      <geometry>
        <mesh filename="package://hexapod/urdf/models/tibia_L_F.stl" scale="0.001 0.001 0.001"/>
      </geometry>
    </visual>
    <inertial>
      <origin rpy="0 0 0" xyz="0 0 0"/>
      <mass value="0.1"/>
      <inertia ixx="0.02" ixy="0.0" ixz="0.0" iyy="0.02" iyz="0.0" izz="0.02"/>
      <!-- <inertia ixx="1.66666666667e-08" ixy="0.0" ixz="0.0"
                      iyy="1.66666666667e-08" iyz="0.0"
                      izz="1.66666666667e-08"/> -->
    </inertial>
  </link>
  <link name="L_F_TIB_link">
    <collision>
      <geometry>
        <mesh filename="package://hexapod/urdf/models/tibia_L_F.stl" scale="0.001 0.001 0.001"/>
      </geometry>
    </collision>
    <visual>
      <geometry>
        <mesh filename="package://hexapod/urdf/models/tibia_L_F.stl" scale="0.001 0.001 0.001"/>
      </geometry>
    </visual>
    <inertial>
      <!-- <origin xyz="0 0 0" rpy="0 0 0" /> -->
      <mass value="0.02769"/>
      <inertia ixx="0.0001500263821" ixy="9.271630416e-05" ixz="-4.990877646e-05" iyy="0.0001250219851" iyz="5.781016591e-05" izz="0.0001940341209"/>
    </inertial>
  </link>
  <joint name="L_F_TIB_joint" type="revolute">
    <origin rpy="0 0 0" xyz="0.027712 0 0"/>
    <parent link="L_F_FEM_link"/>
    <child link="L_F_TIB_link"/>
    <axis rpy="0 0 0" xyz="0 1 0"/>
    <!-- <limit upper="${PI}" lower="${PI}" effort="10000" velocity="1000"/> -->
    <limit effort="1000.0" lower="-1.0" upper="1.0" velocity="0.5"/>
    <!-- <joint_properties damping="1.0" friction="1.0"/> -->
  </joint>
  <gazebo reference="L_F_TIB_link">
    <mu1 value="10.0"/>
    <mu2 value="10.0"/>
    <kp value="10000.0"/>
    <kd value="10000.0"/>
    <material>Gazebo/Green</material>
  </gazebo>
  <link name="L_B_COX_link">
    <collision>
      <geometry>
        <mesh filename="package://hexapod/urdf/models/coxa_L_B.stl" scale="0.001 0.001 0.001"/>
      </geometry>
    </collision>
    <visual>
      <geometry>
        <mesh filename="package://hexapod/urdf/models/coxa_L_B.stl" scale="0.001 0.001 0.001"/>
      </geometry>
    </visual>
    <inertial>
      <!-- <origin xyz="0 0 0" rpy="0 0 0" /> -->
      <mass value="0.02769"/>
      <inertia ixx="0.0001500263821" ixy="-9.271630416e-05" ixz="-4.990877646e-05" iyy="0.0001250219851" iyz="-5.781016591e-05" izz="0.0001940341209"/>
    </inertial>
  </link>
  <joint name="L_B_COX_joint" type="revolute">
    <origin rpy="0 0 0" xyz="0.057077 0.066312 0.007"/>
    <parent link="body_link"/>
    <child link="L_B_COX_link"/>
    <axis rpy="0 0 0" xyz="0 0 1"/>
    <!-- <limit upper="${PI}" lower="${PI}" effort="10000" velocity="1000"/> -->
    <limit effort="1000.0" lower="-1.0" upper="1.0" velocity="0.5"/>
    <!-- <joint_properties damping="1.0" friction="1.0"/> -->
  </joint>
  <gazebo reference="L_B_COX_link">
    <mu1 value="10.0"/>
    <mu2 value="10.0"/>
    <kp value="10000.0"/>
    <kd value="10000.0"/>
    <material>Gazebo/Green</material>
  </gazebo>
  <link name="L_B_FEM_link">
    <collision>
      <geometry>
        <mesh filename="package://hexapod/urdf/models/femur_L_B.stl" scale="0.001 0.001 0.001"/>
      </geometry>
    </collision>
    <visual>
      <geometry>
        <mesh filename="package://hexapod/urdf/models/femur_L_B.stl" scale="0.001 0.001 0.001"/>
      </geometry>
    </visual>
    <inertial>
      <!-- <origin xyz="0 0 0" rpy="0 0 0" /> -->
      <mass value="0.02769"/>
      <inertia ixx="0.0001500263821" ixy="-9.271630416e-05" ixz="-4.990877646e-05" iyy="0.0001250219851" iyz="-5.781016591e-05" izz="0.0001940341209"/>
    </inertial>
  </link>
  <joint name="L_B_FEM_joint" type="revolute">
    <origin rpy="0 0 0" xyz="0.007261 0.017438 0.057284"/>
    <parent link="L_B_COX_link"/>
    <child link="L_B_FEM_link"/>
    <axis rpy="0 0 0" xyz="0 1 0"/>
    <!-- <limit upper="${PI}" lower="${PI}" effort="10000" velocity="1000"/> -->
    <limit effort="1000.0" lower="-1.0" upper="1.0" velocity="0.5"/>
    <!-- <joint_properties damping="1.0" friction="1.0"/> -->
  </joint>
  <gazebo reference="L_B_FEM_link">
    <mu1 value="10.0"/>
    <mu2 value="10.0"/>
    <kp value="10000.0"/>
    <kd value="10000.0"/>
    <material>Gazebo/Blue</material>
  </gazebo>
  <!-- <transmission name="${side}_dock_transmission">
            <type>transmission_interface/SimpleTransmission</type>
            <joint name="dock_${side}_joint"> -->
  <!-- <hardwareInterface>hardware_interface/EffortJointInterface</hardwareInterface> -->
  <!-- <hardwareInterface>EffortJointInterface</hardwareInterface>
            </joint>
            <actuator name="${side}_dock_actuator">
                <mechanicalReduction>7</mechanicalReduction>
                <hardwareInterface>EffortJointInterface</hardwareInterface>
            </actuator>
        </transmission> -->
  <link name="L_B_TIB_link">
    <collision>
      <geometry>
        <mesh filename="package://hexapod/urdf/models/tibia_L_B.stl" scale="0.001 0.001 0.001"/>
      </geometry>
    </collision>
    <visual>
      <geometry>
        <mesh filename="package://hexapod/urdf/models/tibia_L_B.stl" scale="0.001 0.001 0.001"/>
      </geometry>
    </visual>
    <inertial>
      <origin rpy="0 0 0" xyz="0 0 0"/>
      <mass value="0.1"/>
      <inertia ixx="0.02" ixy="0.0" ixz="0.0" iyy="0.02" iyz="0.0" izz="0.02"/>
      <!-- <inertia ixx="1.66666666667e-08" ixy="0.0" ixz="0.0"
                      iyy="1.66666666667e-08" iyz="0.0"
                      izz="1.66666666667e-08"/> -->
    </inertial>
  </link>
  <link name="L_B_TIB_link">
    <collision>
      <geometry>
        <mesh filename="package://hexapod/urdf/models/tibia_L_B.stl" scale="0.001 0.001 0.001"/>
      </geometry>
    </collision>
    <visual>
      <geometry>
        <mesh filename="package://hexapod/urdf/models/tibia_L_B.stl" scale="0.001 0.001 0.001"/>
      </geometry>
    </visual>
    <inertial>
      <!-- <origin xyz="0 0 0" rpy="0 0 0" /> -->
      <mass value="0.02769"/>
      <inertia ixx="0.0001500263821" ixy="-9.271630416e-05" ixz="-4.990877646e-05" iyy="0.0001250219851" iyz="-5.781016591e-05" izz="0.0001940341209"/>
    </inertial>
  </link>
  <joint name="L_B_TIB_joint" type="revolute">
    <origin rpy="0 0 0" xyz="0.027712 0 0"/>
    <parent link="L_B_FEM_link"/>
    <child link="L_B_TIB_link"/>
    <axis rpy="0 0 0" xyz="0 1 0"/>
    <!-- <limit upper="${PI}" lower="${PI}" effort="10000" velocity="1000"/> -->
    <limit effort="1000.0" lower="-1.0" upper="1.0" velocity="0.5"/>
    <!-- <joint_properties damping="1.0" friction="1.0"/> -->
  </joint>
  <gazebo reference="L_B_TIB_link">
    <mu1 value="10.0"/>
    <mu2 value="10.0"/>
    <kp value="10000.0"/>
    <kd value="10000.0"/>
    <material>Gazebo/Green</material>
  </gazebo>
</robot>

